<?xml version="1.0" ?>
<!-- =================================================================================== -->
<!-- |    This document was autogenerated by xacro from urdf/cobolege_torche.xacro     | -->
<!-- |    EDITING THIS FILE BY HAND IS NOT RECOMMENDED                                 | -->
<!-- =================================================================================== -->
<!-- c2n6s300 refers to jaco v2 6DOF non-spherical 3fingers -->
<robot name="cobolege_v0" xmlns:body="http://playerstage.sourceforge.net/gazebo/xmlschema/#body" xmlns:controller="http://playerstage.sourceforge.net/gazebo/xmlschema/#controller" xmlns:gazebo="http://playerstage.sourceforge.net/gazebo/xmlschema/#gz" xmlns:geom="http://playerstage.sourceforge.net/gazebo/xmlschema/#geom" xmlns:interface="http://playerstage.sourceforge.net/gazebo/xmlschema/#interface" xmlns:joint="http://playerstage.sourceforge.net/gazebo/xmlschema/#joint" xmlns:model="http://playerstage.sourceforge.net/gazebo/xmlschema/#model" xmlns:physics="http://playerstage.sourceforge.net/gazebo/xmlschema/#physics" xmlns:renderable="http://playerstage.sourceforge.net/gazebo/xmlschema/#renderable" xmlns:rendering="http://playerstage.sourceforge.net/gazebo/xmlschema/#rendering" xmlns:sensor="http://playerstage.sourceforge.net/gazebo/xmlschema/#sensor" xmlns:xi="http://www.w3.org/2001/XInclude">
  <gazebo>
    <plugin filename="libgazebo_ros_control.so" name="gazebo_ros_control">
      <robotNamespace>cobolege</robotNamespace>
      <robotSimType>gazebo_ros_control/DefaultRobotHWSim</robotSimType>
      <legacyModeNS>true</legacyModeNS>
    </plugin>
  </gazebo>
  <!--Joint Velocity Limits is about 0.9071111 which is roughly 50degree / seconds-->
  <link name="root"/>
  <!-- for gazebo -->
  <link name="world"/>
  <joint name="connect_root_and_world" type="fixed">
    <child link="root"/>
    <parent link="world"/>
    <origin rpy="0 0 0" xyz="0 0 0"/>
  </joint>
  <link name="base_link">
    <visual>
      <origin rpy="0 0 0" xyz="0 0.0 0"/>
      <geometry>
        <mesh filename="package://cobolege_description/meshes/visual/Base.dae"/>
      </geometry>
    </visual>
    <collision>
      <origin rpy="0 0 0" xyz="0 0.0 0"/>
      <geometry>
        <mesh filename="package://cobolege_description/meshes/collision/Base.stl"/>
      </geometry>
    </collision>
    <inertial>
      <origin rpy="0 0 0" xyz="0 0 0"/>
      <mass value="1"/>
      <inertia ixx="1.0" ixy="0.0" ixz="0.0" iyy="1.0" iyz="0.0" izz="1.0"/>
    </inertial>
  </link>
  <link name="link1">
    <visual>
      <origin rpy="0 0 0" xyz="0 0 0"/>
      <geometry>
        <mesh filename="package://cobolege_description/meshes/visual/Link1.dae"/>
      </geometry>
    </visual>
    <collision>
      <origin rpy="0 0 0" xyz="0 0 0"/>
      <geometry>
        <mesh filename="package://cobolege_description/meshes/collision/Link1.stl"/>
      </geometry>
    </collision>
    <inertial>
      <origin rpy="0 0 0" xyz="0 0 0"/>
      <mass value="1"/>
      <inertia ixx="1.0" ixy="0.0" ixz="0.0" iyy="1.0" iyz="0.0" izz="1.0"/>
    </inertial>
  </link>
  <link name="link2">
    <visual>
      <origin rpy="0 0 0" xyz="0 0 0"/>
      <geometry>
        <mesh filename="package://cobolege_description/meshes/visual/Link2.dae"/>
      </geometry>
    </visual>
    <collision>
      <origin rpy="0 0 0" xyz="0 0 0"/>
      <geometry>
        <mesh filename="package://cobolege_description/meshes/collision/Link2.stl"/>
      </geometry>
    </collision>
    <inertial>
      <origin rpy="0 0 0" xyz="0 0 0"/>
      <mass value="1"/>
      <inertia ixx="1.0" ixy="0.0" ixz="0.0" iyy="1.0" iyz="0.0" izz="1.0"/>
    </inertial>
  </link>
  <link name="link3">
    <visual>
      <origin rpy="0 0 0" xyz="0 0 0"/>
      <geometry>
        <mesh filename="package://cobolege_description/meshes/visual/Link3.dae"/>
      </geometry>
    </visual>
    <collision>
      <origin rpy="0 0 0" xyz="0 0 0"/>
      <geometry>
        <mesh filename="package://cobolege_description/meshes/collision/Link3.stl"/>
      </geometry>
    </collision>
    <inertial>
      <origin rpy="0 0 0" xyz="0 0 0"/>
      <mass value="1"/>
      <inertia ixx="1.0" ixy="0.0" ixz="0.0" iyy="1.0" iyz="0.0" izz="1.0"/>
    </inertial>
  </link>
  <link name="link4">
    <visual>
      <origin rpy="0 0 0" xyz="0 0 0 "/>
      <geometry>
        <mesh filename="package://cobolege_description/meshes/visual/Link4.dae"/>
      </geometry>
    </visual>
    <collision>
      <origin rpy="0 0 0" xyz="0 0 0 "/>
      <geometry>
        <mesh filename="package://cobolege_description/meshes/collision/Link4.stl"/>
      </geometry>
    </collision>
    <inertial>
      <origin rpy="0 0 0" xyz="0 0 0"/>
      <mass value="1"/>
      <inertia ixx="1.0" ixy="0.0" ixz="0.0" iyy="1.0" iyz="0.0" izz="1.0"/>
    </inertial>
  </link>
  <link name="link5">
    <visual>
      <origin rpy="0 0 0" xyz="0 0 0 "/>
      <geometry>
        <mesh filename="package://cobolege_description/meshes/visual/Link5.dae"/>
      </geometry>
    </visual>
    <collision>
      <origin rpy="0 0 0" xyz="0 0 0 "/>
      <geometry>
        <mesh filename="package://cobolege_description/meshes/collision/Link5.stl"/>
      </geometry>
    </collision>
    <inertial>
      <origin rpy="0 0 0" xyz="0 0 0"/>
      <mass value="1"/>
      <inertia ixx="1.0" ixy="0.0" ixz="0.0" iyy="1.0" iyz="0.0" izz="1.0"/>
    </inertial>
  </link>
  <link name="link6">
    <visual>
      <origin rpy="0 0 0" xyz="0 0 0 "/>
      <geometry>
        <mesh filename="package://cobolege_description/meshes/visual/Link6.dae"/>
      </geometry>
    </visual>
    <collision>
      <origin rpy="0 0 0" xyz="0 0 0 "/>
      <geometry>
        <mesh filename="package://cobolege_description/meshes/collision/Link6.stl"/>
      </geometry>
    </collision>
    <inertial>
      <origin rpy="0 0 0" xyz="0 0 0"/>
      <mass value="1"/>
      <inertia ixx="1.0" ixy="0.0" ixz="0.0" iyy="1.0" iyz="0.0" izz="1.0"/>
    </inertial>
  </link>
  <link name="end_effector">
        </link>
  <joint name="c2n6s000_joint_1" type="revolute">
    <parent link="base_link"/>
    <child link="link1"/>
    <origin rpy="0 0 0" xyz="0 0 +1.5767e-01"/>
    <axis xyz="0 0 1"/>
    <limit effort="10.0" lower="-3.141592653589793" upper="3.141592653589793" velocity="0.9"/>
  </joint>
  <!--Gazebo Stuff-->
  <!--transmission name="${joint_name}_trans">
            <type>transmission_interface/SimpleTransmission</type>
            <joint name="${robot_name}_${joint_name}">
              <hardwareInterface>hardware_interface/EffortJointInterface</hardwareInterface>
            </joint>
            <actuator name="${joint_name}_actuator">
              <hardwareInterface>hardware_interface/EffortJointInterface</hardwareInterface>
              <mechanicalReduction>160</mechanicalReduction>
            </actuator>
         </transmission-->
  <joint name="c2n6s000_joint_2" type="revolute">
    <parent link="link1"/>
    <child link="link2"/>
    <origin rpy="0 0 0" xyz="0 -1.8797e-02 +5.4745e-02"/>
    <axis xyz="0 1 0"/>
    <limit effort="50.0" lower="-3.141592653589793" upper="3.141592653589793" velocity="0.18"/>
  </joint>
  <!--Gazebo Stuff-->
  <!--transmission name="${joint_name}_trans">
            <type>transmission_interface/SimpleTransmission</type>
            <joint name="${robot_name}_${joint_name}">
              <hardwareInterface>hardware_interface/EffortJointInterface</hardwareInterface>
            </joint>
            <actuator name="${joint_name}_actuator">
              <hardwareInterface>hardware_interface/EffortJointInterface</hardwareInterface>
              <mechanicalReduction>160</mechanicalReduction>
            </actuator>
         </transmission-->
  <joint name="c2n6s000_joint_3" type="revolute">
    <parent link="link2"/>
    <child link="link3"/>
    <origin rpy="0.0 0 0.0" xyz="0.400 +5.9995e-03 0"/>
    <axis xyz="0 1 0"/>
    <limit effort="30.0" lower="-3.141592653589793" upper="3.141592653589793" velocity="0.3"/>
  </joint>
  <!--Gazebo Stuff-->
  <!--transmission name="${joint_name}_trans">
            <type>transmission_interface/SimpleTransmission</type>
            <joint name="${robot_name}_${joint_name}">
              <hardwareInterface>hardware_interface/EffortJointInterface</hardwareInterface>
            </joint>
            <actuator name="${joint_name}_actuator">
              <hardwareInterface>hardware_interface/EffortJointInterface</hardwareInterface>
              <mechanicalReduction>160</mechanicalReduction>
            </actuator>
         </transmission-->
  <joint name="c2n6s000_joint_4" type="revolute">
    <parent link="link3"/>
    <child link="link4"/>
    <origin rpy="0 0.0 0" xyz="+1.2540e-01 +3.5376e-02 0.0"/>
    <axis xyz="1 0 0"/>
    <limit effort="10.0" lower="-3.141592653589793" upper="3.141592653589793" velocity="0.9"/>
  </joint>
  <!--Gazebo Stuff-->
  <!--transmission name="${joint_name}_trans">
            <type>transmission_interface/SimpleTransmission</type>
            <joint name="${robot_name}_${joint_name}">
              <hardwareInterface>hardware_interface/EffortJointInterface</hardwareInterface>
            </joint>
            <actuator name="${joint_name}_actuator">
              <hardwareInterface>hardware_interface/EffortJointInterface</hardwareInterface>
              <mechanicalReduction>160</mechanicalReduction>
            </actuator>
         </transmission-->
  <joint name="c2n6s000_joint_5" type="revolute">
    <parent link="link4"/>
    <child link="link5"/>
    <origin rpy="0 0.0 0" xyz="+1.9188e-01 -3.0250e-02 0"/>
    <axis xyz="0 1 0"/>
    <limit effort="10.0" lower="-3.141592653589793" upper="3.141592653589793" velocity="0.9"/>
  </joint>
  <!--Gazebo Stuff-->
  <!--transmission name="${joint_name}_trans">
            <type>transmission_interface/SimpleTransmission</type>
            <joint name="${robot_name}_${joint_name}">
              <hardwareInterface>hardware_interface/EffortJointInterface</hardwareInterface>
            </joint>
            <actuator name="${joint_name}_actuator">
              <hardwareInterface>hardware_interface/EffortJointInterface</hardwareInterface>
              <mechanicalReduction>160</mechanicalReduction>
            </actuator>
         </transmission-->
  <joint name="c2n6s000_joint_6" type="revolute">
    <parent link="link5"/>
    <child link="link6"/>
    <origin rpy="0 0.0 0" xyz="+2.2750e-02 -8.3250e-02 0"/>
    <axis xyz="1 0 0"/>
    <limit effort="10.0" lower="-3.141592653589793" upper="3.141592653589793" velocity="0.9"/>
  </joint>
  <!--Gazebo Stuff-->
  <!--transmission name="${joint_name}_trans">
            <type>transmission_interface/SimpleTransmission</type>
            <joint name="${robot_name}_${joint_name}">
              <hardwareInterface>hardware_interface/EffortJointInterface</hardwareInterface>
            </joint>
            <actuator name="${joint_name}_actuator">
              <hardwareInterface>hardware_interface/EffortJointInterface</hardwareInterface>
              <mechanicalReduction>160</mechanicalReduction>
            </actuator>
         </transmission-->
  <joint name="fixed_endeffector" type="fixed">
    <parent link="link6"/>
    <child link="end_effector"/>
    <origin rpy="0 0 0" xyz="+4.1015e-02 0 0.0"/>
  </joint>
  <link name="tcp_torche">
    <visual>
      <origin rpy="-0.4411884 -0.5479314 0.7889799" xyz="+2.7294e-02 +3.9027e-02 -1.6754e-01"/>
      <geometry>
        <mesh filename="package://cobolege_description/meshes/visual/Torche.dae"/>
      </geometry>
    </visual>
    <collision>
      <origin rpy="-0.4411884 -0.5479314 0.7889799" xyz="+2.7294e-02 +3.9027e-02 -1.6754e-01"/>
      <geometry>
        <mesh filename="package://cobolege_description/meshes/collision/Torche.stl"/>
      </geometry>
    </collision>
  </link>
  <joint name="tcp_torche_joint" type="fixed">
    <child link="tcp_torche"/>
    <parent link="end_effector"/>
    <origin rpy="0 2.070327 0" xyz="+2.4658e-01 -9.7899e-02 -5.8759e-02"/>
  </joint>
  <joint name="fixed_baselink" type="fixed">
    <parent link="root"/>
    <child link="base_link"/>
    <origin rpy="0 0 0" xyz="0 0 0.0"/>
  </joint>
</robot>
